Using DDP (DistributedDataParallel) with torchrun for 4 GPUs

W1101 15:35:51.110000 2721779 torch/distributed/run.py:793] 
W1101 15:35:51.110000 2721779 torch/distributed/run.py:793] *****************************************
W1101 15:35:51.110000 2721779 torch/distributed/run.py:793] Setting OMP_NUM_THREADS environment variable for each process to be 1 in default, to avoid your system being overloaded, please further tune the variable for optimal performance in your application as needed. 
W1101 15:35:51.110000 2721779 torch/distributed/run.py:793] *****************************************
==> Using CUDA on HPC (4 GPUs available)
  - Batch size per GPU: 10
  - Global batch size: 40
  - Effective batch (with grad accum): 320
  - Samples: 10000
  - Epochs: 5
  - BF16: True
  - Flash Attention: True
==> Using CUDA on HPC (4 GPUs available)
Python: 3.10.14 | packaged by conda-forge | (main, Mar 20 2024, 12:45:18) [GCC 12.3.0]
PyTorch: 2.5.1+cu121
CUDA available: True
CUDA devices: 4
[W1101 15:36:03.742219524 CUDAAllocatorConfig.h:28] Warning: expandable_segments not supported on this platform (function operator())

âœ“ Initialized DDP: 4 processes (rank 0)
  Backend: nccl
  Device for rank 0: cuda:0
================================================================================
UNIFIED CROSS-MODEL ALIGNMENT EXPERIMENTS
==> Using CUDA on HPC (4 GPUs available)
[rank0]: Traceback (most recent call last):
[rank0]:   File "/projects/m000066/sujinesh/LatentWire/experimental/learning/unified_cross_model_experiments.py", line 4682, in <module>
[rank0]:     main()
[rank0]:   File "/projects/m000066/sujinesh/LatentWire/experimental/learning/unified_cross_model_experiments.py", line 4312, in main
[rank0]:     print(f"Timestamp: {datetime.now().isoformat()}")
[rank0]: AttributeError: module 'datetime' has no attribute 'now'
==> Using CUDA on HPC (4 GPUs available)
  - Batch size per GPU: 10
  - Global batch size: 40
  - Effective batch (with grad accum): 320
  - Samples: 10000
  - Epochs: 5
  - BF16: True
  - Flash Attention: True
Python: 3.10.14 | packaged by conda-forge | (main, Mar 20 2024, 12:45:18) [GCC 12.3.0]
PyTorch: 2.5.1+cu121
CUDA available: True
CUDA devices: 4
[W1101 15:36:03.808399300 CUDAAllocatorConfig.h:28] Warning: expandable_segments not supported on this platform (function operator())
  - Batch size per GPU: 10
  - Global batch size: 40
  - Effective batch (with grad accum): 320
  - Samples: 10000
  - Epochs: 5
  - BF16: True
  - Flash Attention: True
Python: 3.10.14 | packaged by conda-forge | (main, Mar 20 2024, 12:45:18) [GCC 12.3.0]
PyTorch: 2.5.1+cu121
CUDA available: True
CUDA devices: 4
  - Batch size per GPU: 10[W1101 15:36:03.817950846 CUDAAllocatorConfig.h:28] Warning: expandable_segments not supported on this platform (function operator())

  - Global batch size: 40
  - Effective batch (with grad accum): 320
  - Samples: 10000
  - Epochs: 5
  - BF16: True
  - Flash Attention: True
Python: 3.10.14 | packaged by conda-forge | (main, Mar 20 2024, 12:45:18) [GCC 12.3.0]
PyTorch: 2.5.1+cu121
CUDA available: True
CUDA devices: 4
[W1101 15:36:03.836343687 CUDAAllocatorConfig.h:28] Warning: expandable_segments not supported on this platform (function operator())
W1101 15:36:04.690000 2721779 torch/distributed/elastic/multiprocessing/api.py:897] Sending process 2721795 closing signal SIGTERM
W1101 15:36:04.690000 2721779 torch/distributed/elastic/multiprocessing/api.py:897] Sending process 2721797 closing signal SIGTERM
W1101 15:36:04.690000 2721779 torch/distributed/elastic/multiprocessing/api.py:897] Sending process 2721798 closing signal SIGTERM
E1101 15:36:05.184000 2721779 torch/distributed/elastic/multiprocessing/api.py:869] failed (exitcode: 1) local_rank: 0 (pid: 2721794) of binary: /marlowe/apps/Mambaforge/24.3.0-0/bin/python
Traceback (most recent call last):
  File "/users/sujinesh/.local/bin/torchrun", line 7, in <module>
    sys.exit(main())
  File "/users/sujinesh/.local/lib/python3.10/site-packages/torch/distributed/elastic/multiprocessing/errors/__init__.py", line 355, in wrapper
    return f(*args, **kwargs)
  File "/users/sujinesh/.local/lib/python3.10/site-packages/torch/distributed/run.py", line 919, in main
    run(args)
  File "/users/sujinesh/.local/lib/python3.10/site-packages/torch/distributed/run.py", line 910, in run
    elastic_launch(
  File "/users/sujinesh/.local/lib/python3.10/site-packages/torch/distributed/launcher/api.py", line 138, in __call__
    return launch_agent(self._config, self._entrypoint, list(args))
  File "/users/sujinesh/.local/lib/python3.10/site-packages/torch/distributed/launcher/api.py", line 269, in launch_agent
    raise ChildFailedError(
torch.distributed.elastic.multiprocessing.errors.ChildFailedError: 
============================================================
/projects/m000066/sujinesh/LatentWire/experimental/learning/unified_cross_model_experiments.py FAILED
------------------------------------------------------------
Failures:
  <NO_OTHER_FAILURES>
------------------------------------------------------------
Root Cause (first observed failure):
[0]:
  time      : 2025-11-01_15:36:04
  host      : n12.cm.cluster
  rank      : 0 (local_rank: 0)
  exitcode  : 1 (pid: 2721794)
  error_file: <N/A>
  traceback : To enable traceback see: https://pytorch.org/docs/stable/elastic/errors.html
============================================================
